[2023-12-21T07:19:16.862+0000] {taskinstance.py:1159} INFO - Dependencies all met for dep_context=non-requeueable deps ti=<TaskInstance: example_dag.process_data manual__2023-12-21T07:14:13.879426+00:00 [queued]>
[2023-12-21T07:19:16.869+0000] {taskinstance.py:1159} INFO - Dependencies all met for dep_context=requeueable deps ti=<TaskInstance: example_dag.process_data manual__2023-12-21T07:14:13.879426+00:00 [queued]>
[2023-12-21T07:19:16.870+0000] {taskinstance.py:1361} INFO - Starting attempt 2 of 2
[2023-12-21T07:19:16.878+0000] {taskinstance.py:1382} INFO - Executing <Task(PythonOperator): process_data> on 2023-12-21 07:14:13.879426+00:00
[2023-12-21T07:19:16.881+0000] {standard_task_runner.py:57} INFO - Started process 543 to run task
[2023-12-21T07:19:16.884+0000] {standard_task_runner.py:84} INFO - Running: ['***', 'tasks', 'run', 'example_dag', 'process_data', 'manual__2023-12-21T07:14:13.879426+00:00', '--job-id', '87', '--raw', '--subdir', 'DAGS_FOLDER/first.py', '--cfg-path', '/tmp/tmp0np0lmv1']
[2023-12-21T07:19:16.886+0000] {standard_task_runner.py:85} INFO - Job 87: Subtask process_data
[2023-12-21T07:19:16.922+0000] {task_command.py:416} INFO - Running <TaskInstance: example_dag.process_data manual__2023-12-21T07:14:13.879426+00:00 [running]> on host aeccb7716600
[2023-12-21T07:19:16.991+0000] {taskinstance.py:1662} INFO - Exporting env vars: AIRFLOW_CTX_DAG_OWNER='niko' AIRFLOW_CTX_DAG_ID='example_dag' AIRFLOW_CTX_TASK_ID='process_data' AIRFLOW_CTX_EXECUTION_DATE='2023-12-21T07:14:13.879426+00:00' AIRFLOW_CTX_TRY_NUMBER='2' AIRFLOW_CTX_DAG_RUN_ID='manual__2023-12-21T07:14:13.879426+00:00'
[2023-12-21T07:19:16.992+0000] {first.py:66} INFO - Data processing completed successfully
[2023-12-21T07:19:16.992+0000] {first.py:69} ERROR - Error in processing data: name 'processed_data' is not defined
[2023-12-21T07:19:16.998+0000] {taskinstance.py:1937} ERROR - Task failed with exception
Traceback (most recent call last):
  File "/opt/airflow/dags/first.py", line 67, in process_data
    return processed_data
NameError: name 'processed_data' is not defined

During handling of the above exception, another exception occurred:

Traceback (most recent call last):
  File "/home/airflow/.local/lib/python3.8/site-packages/airflow/operators/python.py", line 192, in execute
    return_value = self.execute_callable()
  File "/home/airflow/.local/lib/python3.8/site-packages/airflow/operators/python.py", line 209, in execute_callable
    return self.python_callable(*self.op_args, **self.op_kwargs)
  File "/opt/airflow/dags/first.py", line 70, in process_data
    raise AirflowException(f"Error in processing data: {e}")
airflow.exceptions.AirflowException: Error in processing data: name 'processed_data' is not defined
[2023-12-21T07:19:17.001+0000] {taskinstance.py:1400} INFO - Marking task as FAILED. dag_id=example_dag, task_id=process_data, execution_date=20231221T071413, start_date=20231221T071916, end_date=20231221T071917
[2023-12-21T07:19:17.008+0000] {standard_task_runner.py:104} ERROR - Failed to execute job 87 for task process_data (Error in processing data: name 'processed_data' is not defined; 543)
[2023-12-21T07:19:17.025+0000] {local_task_job_runner.py:228} INFO - Task exited with return code 1
[2023-12-21T07:19:17.042+0000] {taskinstance.py:2778} INFO - 0 downstream tasks scheduled from follow-on schedule check
