[2023-12-21T07:43:55.316+0000] {taskinstance.py:1159} INFO - Dependencies all met for dep_context=non-requeueable deps ti=<TaskInstance: example_dag.save_data manual__2023-12-21T07:36:43.879851+00:00 [queued]>
[2023-12-21T07:43:55.323+0000] {taskinstance.py:1159} INFO - Dependencies all met for dep_context=requeueable deps ti=<TaskInstance: example_dag.save_data manual__2023-12-21T07:36:43.879851+00:00 [queued]>
[2023-12-21T07:43:55.323+0000] {taskinstance.py:1361} INFO - Starting attempt 2 of 2
[2023-12-21T07:43:55.331+0000] {taskinstance.py:1382} INFO - Executing <Task(PythonOperator): save_data> on 2023-12-21 07:36:43.879851+00:00
[2023-12-21T07:43:55.334+0000] {standard_task_runner.py:57} INFO - Started process 55 to run task
[2023-12-21T07:43:55.339+0000] {standard_task_runner.py:84} INFO - Running: ['***', 'tasks', 'run', 'example_dag', 'save_data', 'manual__2023-12-21T07:36:43.879851+00:00', '--job-id', '131', '--raw', '--subdir', 'DAGS_FOLDER/first.py', '--cfg-path', '/tmp/tmpeijw3saj']
[2023-12-21T07:43:55.340+0000] {standard_task_runner.py:85} INFO - Job 131: Subtask save_data
[2023-12-21T07:43:55.376+0000] {task_command.py:416} INFO - Running <TaskInstance: example_dag.save_data manual__2023-12-21T07:36:43.879851+00:00 [running]> on host dc6df2984800
[2023-12-21T07:43:55.426+0000] {taskinstance.py:1662} INFO - Exporting env vars: AIRFLOW_CTX_DAG_OWNER='niko' AIRFLOW_CTX_DAG_ID='example_dag' AIRFLOW_CTX_TASK_ID='save_data' AIRFLOW_CTX_EXECUTION_DATE='2023-12-21T07:36:43.879851+00:00' AIRFLOW_CTX_TRY_NUMBER='2' AIRFLOW_CTX_DAG_RUN_ID='manual__2023-12-21T07:36:43.879851+00:00'
[2023-12-21T07:43:55.436+0000] {taskinstance.py:1937} ERROR - Task failed with exception
Traceback (most recent call last):
  File "/home/airflow/.local/lib/python3.8/site-packages/airflow/operators/python.py", line 192, in execute
    return_value = self.execute_callable()
  File "/home/airflow/.local/lib/python3.8/site-packages/airflow/operators/python.py", line 209, in execute_callable
    return self.python_callable(*self.op_args, **self.op_kwargs)
  File "/opt/airflow/dags/first.py", line 74, in save_data
    if not os.path.exists(data_directory):
NameError: name 'os' is not defined
[2023-12-21T07:43:55.442+0000] {taskinstance.py:1400} INFO - Marking task as FAILED. dag_id=example_dag, task_id=save_data, execution_date=20231221T073643, start_date=20231221T074355, end_date=20231221T074355
[2023-12-21T07:43:55.449+0000] {standard_task_runner.py:104} ERROR - Failed to execute job 131 for task save_data (name 'os' is not defined; 55)
[2023-12-21T07:43:55.472+0000] {local_task_job_runner.py:228} INFO - Task exited with return code 1
[2023-12-21T07:43:55.487+0000] {taskinstance.py:2778} INFO - 0 downstream tasks scheduled from follow-on schedule check
